Workbook

Sheet MF_4
A1: DATE | C1: Axis Small Cap Fund | E1: Axis Bluechip Fund | G1: SBI Small Cap Fund | I1: SBI Bluechip Fund | K1: ICICI prudential small cap fund | M1: ICICI prudential bluechip fund | O1: Mirae Asset Large Cap Fund | Q1: Nippon India Small Cap Fund | S1: Nippon India Large Cap Fund | U1: Franklin India Smaller Companies Fund | W1: Quant Small Cap Fund | Y1: Bank of India Small Cap Fund | AA1: Bank of India Bluechip Fund | AC1: Edelweiss Small Cap Fund | AE1: Edelweiss Large Cap Fund | AG1: UTI Small Cap Fund | AI1: Tata Small Cap Fund | AK1: Bandhan Small Cap Fund | AM1: Bandhan Large Cap Fund | AO1: Hdfc Small Cap Fund
A2: TYPE | C2: Small Cap | E2: Large Cap | G2: Small Cap | I2: Large Cap | K2: Small Cap | M2: Large Cap | O2: Large Cap | Q2: Small Cap | S2: Large Cap | U2: Small Cap | W2: Small Cap | Y2: Small Cap | AA2: Large Cap | AC2: Small Cap | AE2: Large Cap | AG2: Small Cap | AI2: Small Cap | AK2: Small Cap | AM2: Large Cap | AO2: Small Cap
A3: Scheme | C3: Regular | E3: Regular | G3: Regular | I3: Regular | K3: Regular | M3: Regular | O3: Regular | Q3: Regular | S3: Regular | U3: Regular | W3: Regular | Y3: Regular | AA3: Regular | AC3: Regular | AE3: Regular | AG3: Regular | AI3: Regular | AK3: Regular | AM3: Regular | AO3: Regular
A5: 45383 | C5: 87.6 | E5: 54.97 | G5: 151.447 | I5: 80.5753 | K5: 76.22 | M5: 96.69 | O5: 97.174 | Q5: 144.2327 | S5: 79.0111 | U5: 150.0304 | W5: 236.082
A6: 45384 | C6: 88.31 | E6: 54.91 | G6: 152.3349 | I6: 80.5901 | K6: 76.83 | M6: 96.48 | O6: 97.052 | Q6: 145.2666 | S6: 79.0297 | U6: 151.4008 | W6: 238.6036
A7: 45385 | C7: 88.81 | E7: 54.83 | G7: 153.5379 | I7: 80.4234 | K7: 77.51 | M7: 96.37 | O7: 97.164 | Q7: 146.16 | S7: 79.2019 | U7: 152.7398 | W7: 240.7754
A8: 45386 | C8: 89.22 | E8: 55.15 | G8: 154.3682 | I8: 80.6113 | K8: 77.76 | M8: 96.37 | O8: 97.39 | Q8: 146.6017 | S8: 79.4045 | U8: 153.533 | W8: 241.6104
A9: 45387 | C9: 89.27 | E9: 55.11 | G9: 154.9984 | I9: 80.6936 | K9: 78.05 | M9: 96.22 | O9: 97.589 | Q9: 147.0745 | S9: 79.6573 | U9: 153.9159 | W9: 243.8755
A10: 45388
A11: 45389
A12: 45390 | C12: 89.26 | E12: 55.51 | G12: 155.1729 | I12: 81.2149 | K12: 78.01 | M12: 97.09 | O12: 98.303 | Q12: 147.414 | S12: 80.1553 | U12: 154.313 | W12: 244.2302
A13: 45391 | C13: 89.05 | E13: 55.51 | G13: 154.9404 | I13: 81.2663 | K13: 77.79 | M13: 96.99 | O13: 98.269 | Q13: 147.0104 | S13: 80.0982 | U13: 154.3693 | W13: 245.2582
A14: 45392 | C14: 89.7 | E14: 55.74 | G14: 156.363 | I14: 81.5339 | K14: 78.21 | M14: 97.47 | O14: 98.81 | Q14: 147.9301 | S14: 80.3572 | U14: 155.3222 | W14: 246.7727
A15: 45393
A16: 45394 | C16: 89.15 | E16: 55.31 | G16: 155.3692 | I16: 80.8902 | K16: 77.79 | M16: 96.45 | O16: 97.972 | Q16: 147.2647 | S16: 79.6519 | U16: 155.1037 | W16: 245.5723
A17: 45395
A18: 45396
A19: 45397 | C19: 88.12 | E19: 54.52 | G19: 153.8999 | I19: 79.961 | K19: 76.92 | M19: 95.54 | O19: 96.716 | Q19: 145.4838 | S19: 78.6132 | U19: 153.7621 | W19: 242.1028
A20: 45398 | C20: 88.29 | E20: 54.14 | G20: 154.3259 | I20: 79.6976 | K20: 77.08 | M20: 95.12 | O20: 96.292 | Q20: 146.0726 | S20: 78.3847 | U20: 154.6943 | W20: 242.7028
A21: 45399
A22: 45400 | C22: 88.13 | E22: 53.84 | G22: 154.4104 | I22: 79.4172 | K22: 77.11 | M22: 94.68 | O22: 95.905 | Q22: 146.2187 | S22: 77.9006 | U22: 154.9481 | W22: 243.4643
A23: 45401 | C23: 88.01 | E23: 54.15 | G23: 155.1999 | I23: 79.7929 | K23: 77.08 | M23: 94.87 | O23: 96.492 | Q23: 146.4296 | S23: 78.4604 | U23: 154.3694 | W23: 243.591
A24: 45402
A25: 45403
A26: 45404 | C26: 88.46 | E26: 54.74 | G26: 156.6142 | I26: 80.3626 | K26: 77.55 | M26: 95.89 | O26: 97.405 | Q26: 148.6977 | S26: 79.2171 | U26: 155.5495 | W26: 246.0378
A27: 45405 | C27: 89.4 | E27: 54.79 | G27: 157.4494 | I27: 80.5905 | K27: 77.96 | M27: 96.09 | O27: 97.787 | Q27: 149.9781 | S27: 79.3513 | U27: 156.7698 | W27: 247.6619
A28: 45406 | C28: 90.1 | E28: 54.9 | G28: 158.6155 | I28: 80.8967 | K28: 78.47 | M28: 96.37 | O28: 98.036 | Q28: 150.8558 | S28: 79.4991 | U28: 157.7147 | W28: 248.8812
A29: 45407 | C29: 90.73 | E29: 54.98 | G29: 159.4081 | I29: 80.8755 | K29: 78.74 | M29: 97.14 | O29: 98.536 | Q29: 152.2396 | S29: 80.2961 | U29: 159.2307 | W29: 250.0449
A30: 45408 | C30: 90.77 | E30: 54.45 | G30: 159.3956 | I30: 80.4151 | K30: 78.87 | M30: 96.98 | O30: 98.08 | Q30: 153.0103 | S30: 79.8894 | U30: 160.0277 | W30: 251.2537
A31: 45409
A32: 45410
A33: 45411 | C33: 90.56 | E33: 54.92 | G33: 159.9382 | I33: 81.0525 | K33: 78.98 | M33: 97.82 | O33: 98.907 | Q33: 153.6303 | S33: 80.7148 | U33: 160.5925 | W33: 252.3833
A34: 45412 | C34: 90.95 | E34: 55.03 | G34: 160.2713 | I34: 81.1084 | K34: 79.44 | M34: 97.79 | O34: 98.716 | Q34: 154.3008 | S34: 80.7215 | U34: 161.1059 | W34: 252.468
A35: 45413
A36: 45414 | C36: 90.92 | E36: 55.25 | G36: 160.6105 | I36: 81.2264 | K36: 79.63 | M36: 98.01 | O36: 98.723 | Q36: 154.9645 | S36: 80.9278 | U36: 161.5322 | W36: 252.6756
A37: 45415 | C37: 90.39 | E37: 54.9 | G37: 159.5067 | I37: 80.8942 | K37: 79.42 | M37: 97.24 | O37: 97.991 | Q37: 154.0879 | S37: 80.3953 | U37: 160.7014 | W37: 250.8884
A38: 45416
A39: 45417
A40: 45418 | C40: 90.18 | E40: 54.83 | G40: 158.8203 | I40: 81.2529 | K40: 79.22 | M40: 96.98 | O40: 97.888 | Q40: 152.6317 | S40: 80.0205 | U40: 160.4843 | W40: 246.9053
A41: 45419 | C41: 89.15 | E41: 54.44 | G41: 157.4357 | I41: 80.8533 | K41: 78.59 | M41: 96.11 | O41: 97.35 | Q41: 150.7162 | S41: 79.4972 | U41: 158.3828 | W41: 242.9962
...

Sheet NAV_Calculator
A1: ISIN | B1: Name of Mutual Fund | C1: Installment | D1: Unit provided | E1: NAV
A2: JUN | B2: Name of Mutual Fund | C2: Installment | D2: Unit provided | E2: NAV
A3: INF769K01010 | B3: Mirae Asset Mutual Fund Large Cap Fund-Regular Growth Plan-Growth -- (SIP) | C3: 1000 | D3: 13.729 | E3: =C3/D3 -> 72.838517
A4: INF200K01T28 | B4: SBI Small Cap Fund Regular Growth -- (SIP) | C4: 1000 | D4: 10.024 | E4: =C4/D4 -> 99.760575
A5: INF200K01180 | B5: SBI BLUE CHIP FUND -- (SIP) | C5: 1000 | D5: 17.519 | E5: =C5/D5 -> 57.080884
A6: INF109K01BI0 | B6: ICICI Prudential Smallcap Fund - Growth -- (SIP) | C6: 1000 | D6: 20.316 | E6: =C6/D6 -> 49.222288
A7: INF109K01BL4 | B7: ICICI Prudential Bluechip Fund - Growth -- (SIP) | C7: 1000 | D7: 15.992 | E7: =C7/D7 -> 62.531266
A8: INF846K01164 | B8: Axis Bluechip Fund -Regular Plan - Growth -- (SIP) | C8: 1000 | D8: 24.581 | E8: =C8/D8 -> 40.681827
A9: INF846K01K01 | B9: Axis Small Cap FundRegular GrowthGrowth -- (SIP) | C9: 1000 | D9: 17.531 | E9: =C9/D9 -> 57.041812
A11: JULY | B11: Name of Mutual Fund | C11: Installment | D11: Unit provided | E11: NAV
A12: INF769K01010 | B12: Mirae Asset Mutual Fund Large Cap Fund-Regular Growth Plan-Growth -- (SIP) | C12: 1000 | D12: 13.598 | E12: =C12/D12 -> 73.540227
A13: INF200K01T28 | B13: SBI Small Cap Fund Regular Growth -- (SIP) | C13: 1000 | D13: 9.977 | E13: =C13/D13 -> 100.23053
A14: INF200K01180 | B14: SBI BLUE CHIP FUND -- (SIP) | C14: 1000 | D14: 17.337 | E14: =C14/D14 -> 57.680106
A15: INF109K01BI0 | B15: ICICI Prudential Smallcap Fund - Growth -- (SIP) | C15: 1000 | D15: 19.836 | E15: =C15/D15 -> 50.41339
A16: INF109K01BL4 | B16: ICICI Prudential Bluechip Fund - Growth -- (SIP) | C16: 1000 | D16: 16.087 | E16: =C16/D16 -> 62.161994
A17: INF846K01K01 | B17: Axis Small Cap FundRegular GrowthGrowth -- (SIP) | C17: 1000 | D17: 17.43 | E17: =C17/D17 -> 57.372347
A18: INF846K01164 | B18: Axis Bluechip Fund -Regular Plan - Growth -- (SIP) | C18: 1000 | D18: 24.672 | E18: =C18/D18 -> 40.531777
A20: AUGUST | B20: Name of Mutual Fund | C20: Installment | D20: Unit provided | E20: NAV
A21: INF769K01010 | B21: Mirae Asset Mutual Fund Large Cap Fund-Regular Growth Plan-Growth -- (SIP) | C21: 1000 | D21: 12.843 | E21: =C21/D21 -> 77.863428
A22: INF200K01T28 | B22: SBI Small Cap Fund Regular Growth -- (SIP) | C22: 1000 | D22: 9.132 | E22: =C22/D22 -> 109.50504
A23: INF200K01180 | B23: SBI BLUE CHIP FUND -- (SIP) | C23: 1000 | D23: 16.269 | E23: =C23/D23 -> 61.466593
A24: INF109K01BI0 | B24: ICICI Prudential Smallcap Fund - Growth -- (SIP) | C24: 1000 | D24: 19.058 | E24: =C24/D24 -> 52.471403
A25: INF109K01BL4 | B25: ICICI Prudential Bluechip Fund - Growth -- (SIP) | C25: 1000 | D25: 15.053 | E25: =C25/D25 -> 66.43194
A26: INF846K01164 | B26: Axis Bluechip Fund -Regular Plan - Growth -- (SIP) | C26: 1000 | D26: 22.742 | E26: =C26/D26 -> 43.971506
A27: INF846K01K01 | B27: Axis Small Cap FundRegular GrowthGrowth -- (SIP) | C27: 1000 | D27: 16.217 | E27: =C27/D27 -> 61.663686
A29: SEPTEMBER | B29: Name of Mutual Fund | C29: Installment | D29: Unit provided | E29: NAV
A30: INF769K01010 | B30: Mirae Asset Mutual Fund Large Cap Fund-Regular Growth Plan-Growth -- (SIP) | C30: 1000 | D30: 12.588 | E30: =C30/D30 -> 79.440737
A31: INF200K01T28 | B31: SBI Small Cap Fund Regular Growth -- (SIP) | C31: 1000 | D31: 8.551 | E31: =C31/D31 -> 116.94539
A32: INF200K01180 | B32: SBI BLUE CHIP FUND -- (SIP) | C32: 1000 | D32: 15.774 | E32: =C32/D32 -> 63.395461
A33: INF109K01BI0 | B33: ICICI Prudential Smallcap Fund - Growth -- (SIP) | C33: 1000 | D33: 18.194 | E33: =C33/D33 -> 54.963175
A34: INF109K01BL4 | B34: ICICI Prudential Bluechip Fund - Growth -- (SIP) | C34: 1000 | D34: 14.707 | E34: =C34/D34 -> 67.994832
A35: INF846K01164 | B35: Axis Bluechip Fund -Regular Plan - Growth -- (SIP) | C35: 1000 | D35: 22.4 | E35: =C35/D35 -> 44.642857
A36: INF846K01K01 | B36: Axis Small Cap FundRegular GrowthGrowth -- (SIP) | C36: 1000 | E36: =C36/D36 -> #DIV/0!
A38: OCTOBER | B38: Name of Mutual Fund | C38: Installment | D38: Unit provided | E38: NAV
A39: INF200K01T28 | B39: SBI Small Cap Fund Regular Growth -- (SIP) | C39: 1000 | D39: 8.684 | E39: =C39/D39 -> 115.15431
A40: INF200K01180 | B40: SBI BLUE CHIP FUND -- (SIP) | C40: 1000 | D40: 16.344 | E40: =C40/D40 -> 61.184533
A41: INF109K01BI0 | B41: ICICI Prudential Smallcap Fund - Growth -- (SIP) | C41: 1000 | D41: 18.514 | E41: =C41/D41 -> 54.013179
A42: INF109K01BL4 | B42: ICICI Prudential Bluechip Fund - Growth -- (SIP) | C42: 1000 | D42: 15.064 | E42: =C42/D42 -> 66.383431
A43: INF846K01164 | B43: Axis Bluechip Fund -Regular Plan - Growth -- (SIP) | C43: 1000 | D43: 22.998 | E43: =C43/D43 -> 43.482042
A44: INF846K01K01 | B44: Axis Small Cap FundRegular GrowthGrowth -- (SIP) | C44: 1000 | D44: 15.69 | E44: =C44/D44 -> 63.734863
...

Sheet Profit&loss
C1: Company Name | E1: Balance | F1: Market Rate | G1: Calculated | H1: Market Value | I1: Investment | J1: V
A2: 1 | B2: INF769K01010 | C2: Mirae Asset Mutual Fund Large Cap Fund-Regular Growth Plan-Growth -- (SIP) | E2: 117.93 | F2: 79.95 | H2: 9428.5 | I2: 9000 | J2: 4.7611556
A3: 2 | B3: INF200K01T28 | C3: SBI Small Cap Fund Regular Growth -- (SIP) | E3: 98.383 | F3: 110.66 | H3: 10887.06 | I3: 9000 | J3: 20.967367
A4: 3 | B4: INF200K01180 | C4: SBI BLUE CHIP FUND -- (SIP) | E4: 274.16 | F4: 62.99 | H4: 17269.34 | I4: 15000 | J4: 15.12892
A5: 4 | B5: INF109K01BI0 | C5: ICICI Prudential Smallcap Fund - Growth -- (SIP) | E5: 201.45 | F5: 52.68 | H5: 10612.39 | I5: 9000 | J5: 17.9154
A6: 5 | B6: INF109K01BL4 | C6: ICICI Prudential Bluechip Fund - Growth -- (SIP) | E6: 157.6 | F6: 68.13 | H6: 10737.29 | I6: 9000 | J6: 19.3032
A7: 6 | B7: INF846K01K01 | C7: Axis Small Cap FundRegular GrowthGrowth -- (SIP) | E7: 279.589 | F7: 62.36 | H7: 17435.17 | I7: 15000 | J7: 16.234467
A8: 7 | B8: INF846K01164 | C8: Axis Bluechip Fund -Regular Plan - Growth -- (SIP) | E8: 232.1 | F8: 45.03 | H8: 10451.46 | I8: 9000 | J8: 16.127367
H9: 86821.21 | I9: 75000 | J9: 15.761616
A12: 1 | B12: INF769K01010 | C12: Mirae Asset Mutual Fund Large Cap Fund-Regular Growth Plan-Growth -- (SIP) | E12: 130.518 | F12: 80.1 | H12: 10454.49 | I12: 10000 | J12: 4.54492
A13: 2 | B13: INF200K01T28 | C13: SBI Small Cap Fund Regular Growth -- (SIP) | E13: 106.934 | F13: 117.53 | H13: 12567.95 | I13: 10000 | J13: 25.67953
A14: 3 | B14: INF200K01180 | C14: SBI BLUE CHIP FUND -- (SIP) | E14: 289.934 | F14: 63.61 | H14: 18442.7 | I14: 16000 | J14: 15.266887
A15: 4 | B15: INF109K01BI0 | C15: ICICI Prudential Smallcap Fund - Growth -- (SIP) | E15: 219.644 | F15: 55.38 | H15: 12163.89 | I15: 10000 | J15: 21.63885
A16: 5 | B16: INF109K01BL4 | C16: ICICI Prudential Bluechip Fund - Growth -- (SIP) | E16: 172.307 | F16: 68.12 | H16: 11737.55 | I16: 10000 | J16: 17.37553
A17: 6 | B17: INF846K01K01 | C17: Axis Small Cap FundRegular GrowthGrowth -- (SIP) | E17: 279.589 | F17: 65.17 | H17: 18220.82 | I17: 15000 | J17: 21.4721
A18: 7 | B18: INF846K01164 | C18: Axis Bluechip Fund -Regular Plan - Growth -- (SIP) | E18: 254.5 | F18: 44.91 | H18: 11429.6 | I18: 10000 | J18: 14.29595
H19: 95017 | I19: 81000 | J19: 17.304932
A22: 1 | B22: INF769K01010 | C22: Mirae Asset Mutual Fund Large Cap Fund-Regular Growth Plan-Growth -- (SIP) | E22: 143.399 | F22: 78.34 | H22: 11233.88 | I22: 11000 | J22: 2.1261605
A23: 2 | B23: INF200K01T28 | C23: SBI Small Cap Fund Regular Growth -- (SIP) | E23: 115.618 | F23: 115.46 | H23: 13349.25 | I23: 11000 | J23: 21.356857
A24: 3 | B24: INF200K01180 | C24: SBI BLUE CHIP FUND -- (SIP) | E24: 306.278 | F24: 61.95 | H24: 18973.92 | I24: 17000 | J24: 11.611306
A25: 4 | B25: INF109K01BI0 | C25: ICICI Prudential Smallcap Fund - Growth -- (SIP) | E25: 238.158 | F25: 53.65 | H25: 12777.18 | I25: 11000 | J25: 16.156152
A26: 5 | B26: INF109K01BL4 | C26: ICICI Prudential Bluechip Fund - Growth -- (SIP) | E26: 187.371 | F26: 67.11 | H26: 12574.47 | I26: 11000 | J26: 14.313344
A27: 6 | B27: INF846K01K01 | C27: Axis Small Cap FundRegular GrowthGrowth -- (SIP) | E27: 295.279 | F27: 63.67 | H27: 18800.41 | I27: 16000 | J27: 17.502587
A28: 7 | B28: INF846K01164 | C28: Axis Bluechip Fund -Regular Plan - Growth -- (SIP) | E28: 277.498 | F28: 43.75 | H28: 12140.54 | I28: 11000 | J28: 10.368523
H29: 99849.65 | I29: 88000 | J29: 13.465511
A32: 1 | B32: INF846K01164 | C32: Axis Bluechip Fund -Regular Plan - Growth -- (SIP) | E32: 299.994 | F32: 44.14 | H32: 13241.74 | I32: 12000 | J32: 10.347793
A33: 2 | B33: INF846K01K01 | C33: Axis Small Cap FundRegular GrowthGrowth -- (SIP) | E33: 310.999 | F33: 63.33 | H33: 19695.57 | I33: 17000 | J33: 15.856275
A34: 3 | B34: INF109K01BL4 | C34: ICICI Prudential Bluechip Fund - Growth -- (SIP) | E34: 201.771 | F34: 68.98 | H34: 13918.16 | I34: 12000 | J34: 15.984697
A35: 4 | B35: INF109K01BI0 | C35: ICICI Prudential Smallcap Fund - Growth -- (SIP) | E35: 256.462 | F35: 54.23 | H35: 13907.93 | I35: 12000 | J35: 15.899452
A36: 5 | B36: INF769K01010 | C36: Mirae Asset Mutual Fund Large Cap Fund-Regular Growth Plan-Growth -- (SIP) | E36: 155.831 | F36: 79.85 | H36: 12443.11 | I36: 12000 | J36: 3.6925446
A37: 6 | B37: INF200K01180 | C37: SBI BLUE CHIP FUND -- (SIP) | E37: 321.89 | F37: 63.64 | H37: 20485.08 | I37: 18000 | J37: 13.805998
A38: 7 | B38: INF200K01T28 | C38: SBI Small Cap Fund Regular Growth -- (SIP) | E38: 124.299 | F38: 114.54 | H38: 14237.21 | I38: 12000 | J38: 18.643396
H39: 107928.79 | I39: 95000 | J39: 13.609255
A43: 1 | B43: INF846K01164 | C43: Axis Bluechip Fund -Regular Plan - Growth -- (SIP) | E43: 322.46 | F43: 44.77 | H43: 14436.53 | I43: 13000 | J43: 11.050262
A44: 2 | B44: INF846K01K01 | C44: Axis Small Cap FundRegular GrowthGrowth -- (SIP) | E44: 326.452 | F44: 64.97 | H44: 21209.59 | I44: 18000 | J44: 17.831033
A45: 3 | B45: INF109K01BL4 | C45: ICICI Prudential Bluechip Fund - Growth -- (SIP) | E45: 215.859 | F45: 71.37 | H45: 15405.86 | I45: 13000 | J45: 18.506592
A46: 4 | B46: INF109K01BI0 | C46: ICICI Prudential Smallcap Fund - Growth -- (SIP) | E46: 274.693 | F46: 55.2 | H46: 15163.05 | I46: 13000 | J46: 16.638877
A47: 5 | B47: INF769K01010 | C47: Mirae Asset Mutual Fund Large Cap Fund-Regular Growth Plan-Growth -- (SIP) | E47: 167.949 | F47: 82.35 | H47: 13830.6 | I47: 13000 | J47: 6.3892308
A48: 6 | B48: INF200K01180 | C48: SBI BLUE CHIP FUND -- (SIP) | E48: 337.285 | F48: 65.28 | H48: 22017.97 | I48: 19000 | J48: 15.884026
A49: 7 | B49: INF200K01T28 | C49: SBI Small Cap Fund Regular Growth -- (SIP) | E49: 132.844 | F49: 117.44 | H49: 15601.2 | I49: 13000 | J49: 20.009223
...

Sheet Sheet1
A1: 47000 | B1: 1000 | C1: =SUM(A1:B1) -> 48000
A2: 52000 | B2: 1000 | C2: =SUM(A2:B2) -> 53000
A3: 14000 | B3: 1000 | C3: =SUM(A3:B3) -> 15000
A4: 14000 | B4: 1000 | C4: =SUM(A4:B4) -> 15000
A5: 14000 | B5: 1000 | C5: =SUM(A5:B5) -> 15000
A6: 15000 | B6: 1000 | C6: =SUM(A6:B6) -> 16000
A7: 14000 | B7: 1000 | C7: =SUM(A7:B7) -> 15000
A8: 14000 | B8: 1000 | C8: =SUM(A8:B8) -> 15000
A9: 19000 | B9: 1000 | C9: =SUM(A9:B9) -> 20000
A10: 26000 | B10: 2000 | C10: =SUM(A10:B10) -> 28000
A11: 47000 | B11: 1000 | C11: =SUM(A11:B11) -> 48000
A12: 47000 | B12: 1000 | C12: =SUM(A12:B12) -> 48000
... A20: 14000 | B20: 1000 | C20: =SUM(A20:B20) -> 15000
